<mujoco model="MuJoCo Model">
  <!-- This file specifies things in degrees. The code/simulator uses radians -->
  <compiler angle="radian"/>
  <option timestep="0.001" integrator="RK4"/>
  <visual>
    <headlight ambient="1 1 1"/>
  </visual>
  <default class="main">
    <joint damping="0.01"/>
    <geom rgba="1 1 1 1"/>
    <default class="wheel">
      <geom size="0.03 0.01 0" type="cylinder"/>
    </default>
    <default class="decor">
      <site type="box"/>
    </default>
  </default>
  <asset>
    <texture type="2d" name="grid" builtin="checker" rgb1="0.1 0.2 0.3" rgb2="0.2 0.3 0.4" width="512" height="512"/>
    <material name="grid" texture="grid" texuniform="true" reflectance="0.05"/>
    <mesh name="chasis" vertex="9 2 0 -10 10 10 9 -2 0 10 3 -10 10 -3 -10 -8 10 -10 -10 -10 10 -8 -10 -10 -5 0 20" scale="0.01 0.006 0.0015"/>
  </asset>
  <worldbody>
    <geom size="50 50 0.01" type="plane" material="grid"/>
    <body name="car" pos="0 0 0.03" quat="0.99999 0 -0.00436331 0">
      <joint type="free" limited="false" actuatorfrclimited="false" damping="0"/>
      <site name="wheelbase" pos="0 0 0"/>
      <body name="left wheel" pos="0 0.03 0" quat="0.707107 -0.707107 0 0">
        <joint name="left" pos="0 0 0" axis="0 0 1"/>
        <geom class="wheel" mass="0.01"/>
        <site class="decor" pos="0 0 0" size="0.006 0.025 0.012"/>
        <site class="decor" pos="0 0 0" size="0.025 0.006 0.012"/>
      </body>
      <body name="right wheel" pos="0 -0.03 0" quat="0.707107 -0.707107 0 0">
        <joint name="right" pos="0 0 0" axis="0 0 1"/>
        <geom class="wheel" mass="0.01"/>
        <site name="torque_sensor_mnt" pos="0 0 0"/>
        <site class="decor" pos="0 0 0" size="0.006 0.025 0.012"/>
        <site class="decor" pos="0 0 0" size="0.025 0.006 0.012"/>
      </body>
      <body name="beam" pos="0 0 0.4">
        <geom name="legL" size="0.01 0.25" pos="0 0.03 -0.1" type="capsule" mass="0.01"/>
        <geom name="legR" size="0.01 0.25" pos="0 -0.03 -0.1" type="capsule" mass="0.01"/>
        <body name="ballbody" pos="0 0 0.1">
          <geom name="ballgeom" size="0.1 0.1 0.1" type="box" mass="3" rgba="0.7 0.7 0.7 1"/>
          <site name="accelerometer_center" pos="0 0 0" rgba="0 1 0 1"/>
        </body>
      </body>
    </body>
  </worldbody>
  <tendon>
    <fixed name="forward">
      <joint joint="left" coef="1"/>
      <joint joint="right" coef="1"/>
    </fixed>
    <fixed name="turn">
      <joint joint="left" coef="-0.5"/>
      <joint joint="right" coef="0.5"/>
    </fixed>
  </tendon>
  <actuator>
    <general name="forward" tendon="forward" ctrlrange="-100 100"/>
  </actuator>
  <sensor>
    <accelerometer site="accelerometer_center" name="accelerometer"/>
    <framepos objtype="site" objname="wheelbase" name="base_position"/>
    <framelinvel objtype="site" objname="wheelbase" name="base_velocity"/>
    <frameangvel objtype="site" objname="accelerometer_center" name="base_ang_velocity"/>
    <torque site="torque_sensor_mnt" name="wheel_torque"/>
    <jointvel joint="right" name="wheel_vel"/>
  </sensor>
</mujoco>
