<mujoco>
  <!-- This file specifies angles in degrees. The code/simulator uses radians -->
  <compiler autolimits="true" angle="degree"/>

  <asset>
    <texture name="grid" type="2d" builtin="checker" width="512" height="512" rgb1=".1 .2 .3" rgb2=".2 .3 .4"/>
    <material name="grid" texture="grid" texrepeat="1 1" texuniform="true" reflectance=".05"/>
  </asset>

  <asset>
    <mesh file="Basis_m.stl"/>
  </asset>

  <visual>
    <headlight ambient="0.5 0.5 0.5" />
    
  </visual>

  <option timestep="0.001" integrator="RK4"/>

  <default>
    <geom rgba="1. 1. 1. 1."/>
    <default class="wheel">
      <geom type="cylinder" size=".03 .01"/>
    </default>
    <default class="decor">
      <site type="box"/>
    </default>
  </default>

  <worldbody>
    <geom type="plane" size="50 50 .01" material="grid"/>
    <body name="pendulum" pos="0.25 0 .03" euler="0 0 0">

        <freejoint/>
        
        <site name="wheelbase" pos="0 0 0"/>
        <geom name="wheelbase_viz" type="box" pos="0 0 0" size=".01 .01 .01" mass="0.001" rgba="0.0 1.0 0.0 1.0"/>

        <site name="accel_site" pos="0 0 0.37"/>
        <geom name="accel" type="box" pos="0 0 0.37" size=".01 .01 .01" mass="0" rgba="0.0 1.0 0.0 1.0"/>

        <body name="leftwheel" pos=".0 .06 0" zaxis="0 1 0">
            <joint name="left"/>
            <geom class="wheel" mass="0.150"/>
            <site class="decor" size=".006 .025 .012"/>
            <site class="decor" size=".025 .006 .012"/>
        </body>

        <body name="rightwheel" pos=".0 -.06 0" zaxis="0 1 0">
            <joint name="right"/>
            <site name="torque_sensor_mnt" pos="0 0 0"/>
            <geom class="wheel" mass="0.150"/>
            <site class="decor" size=".006 .025 .012"/>
            <site class="decor" size=".025 .006 .012"/>
        </body>

        <body name="beam" pos="0 0 0.25">
            <geom type="mesh" mesh="Basis_m" pos="0 0 0.033" size="0.01 0.01 0.01" euler="90 90 0" mass="0.810"/>
        </body>
      
    </body>
  </worldbody>

  <actuator>
    <motor name="forward_left" joint="left" gear="1"/>
    <motor name="forward_right" joint="right" gear="1"/>
  </actuator>

  <sensor>
    <accelerometer name="accelerometer" site="accel_site" noise="0.0"/>
    <gyro name="gyro" site="accel_site" noise="0.0"/>
    <framequat name="angle_sensor" objtype="site" objname="wheelbase"/>
    <framepos name="base_position" objtype="site" objname="wheelbase"/>
    <framelinvel name="base_velocity" objtype="site" objname="wheelbase"/>
    <frameangvel name="base_ang_velocity" objtype="site" objname="wheelbase"/>
    <torque name="wheel_torque" site="torque_sensor_mnt"/>
    <jointvel name="wheel_vel" joint="right"/>
    <jointpos name="wheel_pos" joint="right"/>
  </sensor>
</mujoco>